#VRML_SIM R2023a utf8

EXTERNPROTO "https://raw.githubusercontent.com/cyberbotics/webots/R2023a/projects/objects/backgrounds/protos/TexturedBackground.proto"
EXTERNPROTO "https://raw.githubusercontent.com/cyberbotics/webots/R2023a/projects/objects/backgrounds/protos/TexturedBackgroundLight.proto"
EXTERNPROTO "https://raw.githubusercontent.com/cyberbotics/webots/R2023a/projects/objects/floors/protos/RectangleArena.proto"
EXTERNPROTO "https://raw.githubusercontent.com/cyberbotics/webots/R2023a/projects/appearances/protos/Grass.proto"

WorldInfo {
}
Viewpoint {
  orientation 0.1584182729475982 0.12711079124869126 -0.9791560128725308 1.809715987988788
  position 0.4952166832037147 1.769667030621502 0.9718245589536628
}
TexturedBackground {
}
TexturedBackgroundLight {
}
RectangleArena {
  floorSize 5 5
  floorAppearance Grass {
  }
}
Robot {
  translation 0 0 0.05
  rotation 0 1 0 0
  children [
    Transform {
      children [
        Solid {
          children [
            DEF base Shape {
              appearance PBRAppearance {
                baseColor 0 0 0
                roughness 1
                metalness 0
              }
              geometry Box {
                size 0.2 0.2 0.1
              }
            }
          ]
        }
      ]
    }
    HingeJoint {
      jointParameters HingeJointParameters {
        position 7.918496399533684e-07
        axis 0 0 1
        anchor 0 0 0.075
      }
      device [
        RotationalMotor {
          name "m1"
        }
      ]
      endPoint Solid {
        translation 1.6354518404021052e-11 1.6354550664129517e-11 0.07499383811492616
        children [
          DEF link1 Shape {
            appearance PBRAppearance {
              baseColor 0 0 1
              roughness 1
              metalness 0
            }
            geometry Cylinder {
              height 0.05
              radius 0.05
            }
          }
          HingeJoint {
            jointParameters HingeJointParameters {
              position 0.05000025728947842
              anchor 0.07 0 0.025
            }
            device [
              RotationalMotor {
                name "m2"
              }
            ]
            endPoint Solid {
              translation 0.07 -0.004748045492668024 0.1198812735159038
              rotation 1 0 0 0
              children [
                DEF link2 Shape {
                  appearance PBRAppearance {
                    baseColor 0.5 0 0.5
                    roughness 1
                    metalness 0
                  }
                  geometry Cylinder {
                    height 0.2
                    radius 0.02
                  }
                }
                HingeJoint {
                  jointParameters HingeJointParameters {
                    anchor -0.04 0 0.1
                  }
                  device [
                    RotationalMotor {
                      name "m3"
                    }
                  ]
                  endPoint Solid {
                    translation -0.04 0 0.2
                    rotation 1 0 0 0
                    children [
                      DEF link3 Shape {
                        appearance PBRAppearance {
                          baseColor 0 0.5 1
                          roughness 1
                          metalness 0
                        }
                        geometry Cylinder {
                          height 0.2
                          radius 0.02
                        }
                      }
                      HingeJoint {
                        jointParameters HingeJointParameters {
                          axis 0 0 1
                          anchor 0 0 0.1
                        }
                        device [
                          RotationalMotor {
                            name "m4"
                          }
                        ]
                        endPoint Solid {
                          translation 0 0 0.15
                          children [
                            DEF link4 Shape {
                              appearance PBRAppearance {
                                baseColor 0.5 0.2 0.7
                                roughness 1
                                metalness 0
                              }
                              geometry Cylinder {
                                height 0.1
                                radius 0.02
                              }
                            }
                            HingeJoint {
                              jointParameters HingeJointParameters {
                                anchor 0 0 0.05
                              }
                              device [
                                RotationalMotor {
                                  name "m5"
                                }
                              ]
                              endPoint Solid {
                                translation 0 0 0.075
                                rotation 1 0 0 0
                                children [
                                  DEF link5 Shape {
                                    appearance PBRAppearance {
                                      baseColor 1 0 0
                                      roughness 1
                                      metalness 0
                                    }
                                    geometry Box {
                                      size 0.01 0.01 0.05
                                    }
                                  }
                                  Solid {
                                    translation 0 0 0.075
                                    rotation 1 0 0 1.57
                                    children [
                                      DEF bat Shape {
                                        appearance PBRAppearance {
                                          baseColor 1 0 0
                                          roughness 1
                                          metalness 0
                                        }
                                        geometry Cylinder {
                                          height 0.01
                                          radius 0.05
                                        }
                                      }
                                    ]
                                    boundingObject USE bat
                                    physics Physics {
                                    }
                                  }
                                ]
                                boundingObject USE link5
                                physics Physics {
                                }
                              }
                            }
                          ]
                          boundingObject USE link4
                          physics Physics {
                          }
                        }
                      }
                    ]
                    boundingObject USE link3
                    physics Physics {
                    }
                  }
                }
              ]
              boundingObject USE link2
              physics Physics {
              }
            }
          }
        ]
        name "solid(1)"
        boundingObject USE link1
        physics Physics {
        }
      }
    }
  ]
  boundingObject USE base
  physics Physics {
  }
  controller "arm_controller"
}
