#VRML_SIM R2023a utf8

EXTERNPROTO "https://raw.githubusercontent.com/cyberbotics/webots/R2023a/projects/objects/backgrounds/protos/TexturedBackground.proto"
EXTERNPROTO "https://raw.githubusercontent.com/cyberbotics/webots/R2023a/projects/objects/backgrounds/protos/TexturedBackgroundLight.proto"
EXTERNPROTO "https://raw.githubusercontent.com/cyberbotics/webots/R2023a/projects/objects/floors/protos/RectangleArena.proto"

WorldInfo {
}
Viewpoint {
  orientation 0.050653402169366236 0.40433714186820635 -0.913206279300859 0.2726056225459243
  position -4.761156494667594 0.8070244207891987 0.7910177722343538
}
TexturedBackground {
}
TexturedBackgroundLight {
}
RectangleArena {
  floorSize 100 100
}
Robot {
  translation 0 0 0.08
  children [
    Transform {
      rotation 0.7071067811865475 0 0.7071067811865475 0.6545003061004253
      children [
        HingeJoint {
          jointParameters HingeJointParameters {
            position 1.5265566588595902e-16
            axis 0 1 0
            anchor -0.075 1 0
          }
          device [
            RotationalMotor {
              name "RM1"
            }
          ]
          endPoint Solid {
            translation 1.5265566588595902e-16 0 0.28000000000000025
            rotation 1.6287176956971712e-16 3.076536813572957e-16 1 1.3926996938995746
            children [
              Shape {
                appearance PBRAppearance {
                  baseColor 0.8 1 1
                  metalness 0
                }
                geometry Cylinder {
                  height 0.5
                  radius 0.06
                }
              }
              HingeJoint {
                jointParameters HingeJointParameters {
                  position 1.5265566588595902e-16
                  axis 0 1 0
                }
                device [
                  RotationalMotor {
                    name "RM2"
                  }
                ]
                endPoint Solid {
                  translation 0 -1.2878587085651817e-16 0.4800000000000001
                  rotation 1 0 0 0
                  children [
                    HingeJoint {
                      jointParameters HingeJointParameters {
                        axis 0 1 0
                      }
                      device [
                        RotationalMotor {
                          name "RM3"
                        }
                      ]
                    }
                    Shape {
                      appearance PBRAppearance {
                        baseColor 0.6 1 1
                        metalness 0
                      }
                      geometry Cylinder {
                        height 0.5
                        radius 0.04
                      }
                    }
                  ]
                }
              }
            ]
          }
        }
      ]
    }
    Transform {
      scale 2 2 2
      children [
        Shape {
          appearance PBRAppearance {
            baseColor 1 0.333333 0
            metalness 0
          }
          geometry Cylinder {
            height 0.1
            radius 0.05
          }
        }
      ]
    }
  ]
  controller "my_controller1"
}
